Step 1: Getting list of tasks
Traceback (most recent call last):
  File "/usr/lib/python3/dist-packages/urllib3/connectionpool.py", line 557, in urlopen
    body=body, headers=headers)
  File "/usr/lib/python3/dist-packages/urllib3/connectionpool.py", line 382, in _make_request
    conn.request(method, url, **httplib_request_kw)
  File "/usr/lib/python3.4/http/client.py", line 1088, in request
    self._send_request(method, url, body, headers)
  File "/usr/lib/python3.4/http/client.py", line 1126, in _send_request
    self.endheaders(body)
  File "/usr/lib/python3.4/http/client.py", line 1084, in endheaders
    self._send_output(message_body)
  File "/usr/lib/python3.4/http/client.py", line 922, in _send_output
    self.send(msg)
  File "/usr/lib/python3.4/http/client.py", line 857, in send
    self.connect()
  File "/usr/lib/python3.4/http/client.py", line 834, in connect
    self.timeout, self.source_address)
  File "/usr/lib/python3.4/socket.py", line 512, in create_connection
    raise err
  File "/usr/lib/python3.4/socket.py", line 503, in create_connection
    sock.connect(sa)
ConnectionRefusedError: [Errno 111] Connection refused

During handling of the above exception, another exception occurred:

Traceback (most recent call last):
  File "/usr/lib/python3/dist-packages/requests/adapters.py", line 330, in send
    timeout=timeout
  File "/usr/lib/python3/dist-packages/urllib3/connectionpool.py", line 607, in urlopen
    raise MaxRetryError(self, url, e)
urllib3.exceptions.MaxRetryError: HTTPConnectionPool(host='localhost', port=5000): Max retries exceeded with url: /tasks (Caused by <class 'ConnectionRefusedError'>: [Errno 111] Connection refused)

During handling of the above exception, another exception occurred:

Traceback (most recent call last):
  File "./app.py", line 121, in <module>
    do_Tests(argURI)
  File "./app.py", line 72, in do_Tests
    returnList = do_printAllTasks(wsURI)
  File "./app.py", line 22, in do_printAllTasks
    data = get_data(taskURI)
  File "./app.py", line 28, in get_data
    r = requests.get(taskURI + "tasks")
  File "/usr/lib/python3/dist-packages/requests/api.py", line 55, in get
    return request('get', url, **kwargs)
  File "/usr/lib/python3/dist-packages/requests/api.py", line 44, in request
    return session.request(method=method, url=url, **kwargs)
  File "/usr/lib/python3/dist-packages/requests/sessions.py", line 455, in request
    resp = self.send(prep, **send_kwargs)
  File "/usr/lib/python3/dist-packages/requests/sessions.py", line 558, in send
    r = adapter.send(request, **kwargs)
  File "/usr/lib/python3/dist-packages/requests/adapters.py", line 378, in send
    raise ConnectionError(e)
requests.exceptions.ConnectionError: HTTPConnectionPool(host='localhost', port=5000): Max retries exceeded with url: /tasks (Caused by <class 'ConnectionRefusedError'>: [Errno 111] Connection refused)

=================================
Tue Oct 13 19:52:27 EDT 2015


